Workbook

Sheet ods_project_ids
A1: OPR Project ID | B1: CARB Project ID | C1: Reporting Period | D1: Project Type | E1: Early Action/ Compliance | F1: Reporting Period Start Date | G1: Reporting Period End Date | H1: Vintage | I1: Offset Project Name | J1: Offset Project Operator | K1: Verification Body | L1: CARB Issuance ID | M1: Project Documentation | N1: ARB Offset Credits Issued | O1: type (ref, foam, mixed, ambiguous) | P1: protocol | Q1: cfc-11-ratio-p | R1: cfc-12-ratio-p | S1: cfc-13-ratio-p | T1: cfc-113-ratio-p | U1: cfc-114-ratio-p | V1: cfc-115-ratio-p | W1: hcfc-22-ratio-p | X1: hcfc-141b-ratio-p | Y1: drop | Z1: notes | AA1: cfc-11-ratio-a | AB1: cfc-12-ratio-a | AC1: cfc-13-ratio-a | AD1: cfc-113-ratio-a | AE1: cfc-114-ratio-a | AF1: cfc-115-ratio-a | AG1: hcfc-22-ratio-a | AH1: hcfc-141b-ratio-a
A2: ACR1007 | B2: CAOD1007 | C2: 1 | D2: ODS | E2: COP | F2: 45195 | G2: 45317 | H2: 2024 | I2: A-Gas 3-2023B | J2: A-Gas US, Inc. | K2: Dillon Consulting Limited | L2: CAOD1007-A | M2: https://greentrace.ice.com/acr/projects/registry/ACR_REGISTRY/project/P2323C9VS725 | N2: 79565 | O2: ref | P2: 2014 | Q2: 0.00092864841 | R2: 0.75226867 | S2: 0 | T2: 0.21644282 | U2: 0.017259385 | V2: 0.013100476 | W2: 0 | X2: 0 | AA2: 0.0009 | AB2: 0.7538 | AC2: 0 | AD2: 0.2112 | AE2: 0.0176 | AF2: 0.0164 | AG2: 0 | AH2: 0
A3: ACR1013 | B3: CAOD1013 | C3: 1 | D3: ODS | E3: COP | F3: 45378 | G3: 45415 | H3: 2024 | I3: Tradewater ODS 54 | J3: Tradewater, LLC | K3: SES, Inc. | L3: CAOD1013-A | M3: https://greentrace.ice.com/acr/projects/registry/ACR_REGISTRY/project/P2323C9VPD25 | N3: 92445 | O3: ref | P3: 2014 | Q3: 0.0992 | R3: 0.8762 | S3: 0 | T3: 0.0064 | U3: 0.0181 | V3: 0.0002 | W3: 0 | X3: 0 | AA3: 0.098 | AB3: 0.8771 | AC3: 0 | AD3: 0.0063 | AE3: 0.0185 | AF3: 0.0002 | AG3: 0 | AH3: 0
A4: ACR1020 | B4: CAOD1020 | C4: 1 | D4: ODS | E4: COP | F4: 45362 | G4: 45376 | H4: 2024 | I4: Hudson Tech 2024-1 | J4: Hudson Technologies Company | K4: SES, Inc. | L4: CAOD1020-A | M4: https://greentrace.ice.com/acr/projects/registry/ACR_REGISTRY/project/P2423C9VYN24 | N4: 83176 | O4: ref | P4: 2014 | Q4: 0.0002 | R4: 0.6724 | S4: 0 | T4: 0.3238 | U4: 0 | V4: 0.0036 | W4: 0 | X4: 0 | AA4: 0.0002 | AB4: 0.6776 | AC4: 0 | AD4: 0.3177 | AE4: 0 | AF4: 0.0045 | AG4: 0 | AH4: 0
A5: ACR1022 | B5: CAOD1022 | C5: 1 | D5: ODS | E5: COP | F5: 45300 | G5: 45340 | H5: 2024 | I5: Tradewater ODS 53B | J5: Tradewater, LLC | K5: SCS Global Services | L5: CAOD1022-A | M5: https://greentrace.ice.com/acr/projects/registry/ACR_REGISTRY/project/P2323C9VR625 | N5: 78611 | O5: ref | P5: 2014 | Q5: 0.0596 | R5: 0.9159 | S5: 0 | T5: 0.0218 | U5: 0.0016 | V5: 0.001 | W5: 0 | X5: 0 | AA5: 0.0588 | AB5: 0.9167 | AC5: 0.0002 | AD5: 0.0213 | AE5: 0.0016 | AF5: 0.0012 | AG5: 0 | AH5: 0
A6: ACR1040 | B6: CAOD1040 | C6: 1 | D6: ODS | E6: COP | F6: 45475 | G6: 45478 | H6: 2024 | I6: Tradewater ODS 55 | J6: Tradewater, LLC | K6: SES, Inc. | L6: CAOD1040-A | M6: https://greentrace.ice.com/acr/projects/registry/ACR_REGISTRY/project/P2423C9VQ425 | N6: 130298 | O6: ref | P6: 2014 | Q6: 0.0003 | R6: 0.9709 | S6: 0 | T6: 0 | U6: 0.0282 | V6: 0.0006 | W6: 0 | X6: 0 | AA6: 0.0003 | AB6: 0.9702 | AC6: 0 | AD6: 0 | AE6: 0.0287 | AF6: 0.0008 | AG6: 0 | AH6: 0
A7: ACR1042 | B7: CAOD1042 | C7: 1 | D7: ODS | E7: COP | F7: 45371 | G7: 45469 | H7: 2024 | I7: A-Gas 1-2024 | J7: A-Gas US, Inc. | K7: Dillon Consulting Limited | L7: CAOD1042-A | M7: https://greentrace.ice.com/acr/projects/registry/ACR_REGISTRY/project/P2323C9VS624 | N7: 92278 | O7: ref | P7: 2014 | Q7: 0.193 | R7: 0.6716 | S7: 0 | T7: 0.1005 | U7: 0.0217 | V7: 0.0132 | W7: 0 | X7: 0 | AA7: 0.1908 | AB7: 0.6725 | AC7: 0 | AD7: 0.098 | AE7: 0.0221 | AF7: 0.0166 | AG7: 0 | AH7: 0
A8: ACR1067 | B8: CAOD1067 | C8: 1 | D8: ODS | E8: COP | F8: 45538 | G8: 45540 | H8: 2024 | I8: Tradewater ODS 56 | J8: Tradewater, LLC | K8: SES, Inc. | L8: CAOD1067-A | M8: https://greentrace.ice.com/acr/projects/registry/ACR_REGISTRY/project/P2423C9VPU24 | N8: 63169 | O8: ref | P8: 2014 | Q8: 0 | R8: 0.9993 | S8: 0 | T8: 0 | U8: 0.0005 | V8: 0.0002 | W8: 0 | X8: 0 | AA8: 0 | AB8: 0.9992 | AC8: 0 | AD8: 0 | AE8: 0.0005 | AF8: 0.0002 | AG8: 0 | AH8: 0
A9: ACR1076 | B9: CAOD1076 | C9: 1 | D9: ODS | E9: COP | F9: 45482 | G9: 45533 | H9: 2024 | I9: Hudson Tech 2024-2 | J9: Hudson Technologies Company | K9: First Environment of California, Inc. | L9: CAOD1076-A | M9: https://greentrace.ice.com/acr/projects/registry/ACR_REGISTRY/project/P2323C9VVL22 | N9: 120685 | O9: ref | P9: 2014 | Q9: 0.4959 | R9: 0.0029 | S9: 0 | T9: 0.4288 | U9: 0.0717 | V9: 0.0007 | W9: 0 | X9: 0 | AA9: 0.4975 | AB9: 0.0029 | AC9: 0 | AD9: 0.4243 | AE9: 0.0744 | AF9: 0.0009 | AG9: 0 | AH9: 0
A10: ACR1090 | B10: CAOD1090 | C10: 1 | D10: ODS | E10: COP | F10: 45588 | G10: 45591 | H10: 2024 | I10: Tradewater ODS 57 | J10: Tradewater, LLC | K10: SES, Inc. | L10: CAOD1090-A | M10: https://greentrace.ice.com/acr/projects/registry/ACR_REGISTRY/project/P2423C9VQE25 | N10: 67943 | O10: ref | P10: 2014 | Q10: 0.084 | R10: 0.9103 | S10: 0 | T10: 0.0056 | U10: 0.0001 | V10: 0 | W10: 0 | X10: 0 | AA10: 0.083 | AB10: 0.9115 | AC10: 0 | AD10: 0.0054 | AE10: 0.0001 | AF10: 0 | AG10: 0 | AH10: 0
A11: ACR1109 | B11: CAOD1109 | C11: 1 | D11: ODS | E11: COP | F11: 45602 | G11: 45616 | H11: 2024 | I11: Hudson Tech 2024-3 | J11: Hudson Technologies Company | K11: First Environment of California, Inc. | L11: CAOD1109-A | M11: https://greentrace.ice.com/acr/projects/registry/ACR_REGISTRY/project/P2423C9VW523 | N11: 45693 | O11: ref | P11: 2014 | Q11: 0.959 | R11: 0.0005 | S11: 0 | T11: 0.0382 | U11: 0.0021 | V11: 0.0001 | W11: 0 | X11: 0 | AA11: 0.9594 | AB11: 0.0005 | AC11: 0 | AD11: 0.0377 | AE11: 0.0022 | AF11: 0.0001 | AG11: 0 | AH11: 0
A12: ACR1163 | B12: CAOD1163 | C12: 1 | D12: ODS | E12: COP | F12: 45722 | G12: 45742 | H12: 2025 | I12: Hudson Tech 2025-1 | J12: Hudson Technologies Company | K12: First Environment of California, Inc. | L12: CAOD1163-A | M12: https://greentrace.ice.com/acr/projects/registry/ACR_REGISTRY/project/P2323C9VW522 | N12: 61040 | O12: ref | P12: 2014 | Q12: 0.9969 | R12: 0.0002 | S12: 0 | T12: 0.0017 | U12: 0.0011 | V12: 0 | W12: 0 | X12: 0 | AA12: 0.9969 | AB12: 0.0003 | AC12: 0 | AD12: 0.0017 | AE12: 0.0011 | AF12: 0 | AG12: 0 | AH12: 0
A13: ACR170 | B13: CAOD5002 | C13: 1 | D13: ODS | E13: COP | F13: 40996 | G13: 41175 | H13: 2012 | I13: ECC ODS Destruction 2012 | J13: Environmental Credit Corp. | K13: SCS Engineers | L13: CAOD5002-A | M13: https://greentrace.ice.com/acr/projects/registry/ACR_REGISTRY/project/P2423C9VRV23 | N13: 306517 | O13: ref | P13: 2011 | Q13: 0.0281 | R13: 0.9592 | S13: 0 | T13: 0 | U13: 0.0108 | V13: 0.0018 | W13: 0 | X13: 0 | AA13: 0.0277 | AB13: 0.959 | AC13: 0 | AD13: 0 | AE13: 0.011 | AF13: 0.0022 | AG13: 0 | AH13: 0
... A19: ACR195 | B19: CAOD5049 | C19: 1 | D19: ODS | E19: COP | F19: 41704 | G19: 41730 | H19: 2014 | I19: EOS ARB ODS 2014-1 | J19: EOS Climate, Inc. | K19: NSF International | L19: CAOD5049-A | M19: https://greentrace.ice.com/acr/projects/registry/ACR_REGISTRY/project/P2423C9VXL23 | N19: 122080 | O19: ref | P19: 2011 | Q19: 0.2537 | R19: 0.7368 | S19: 0 | T19: 0.0008 | U19: 0.0066 | V19: 0.0022 | W19: 0 | X19: 0 | AA19: 0.251 | AB19: 0.7388 | AC19: 0 | AD19: 0.0007 | AE19: 0.0067 | AF19: 0.0027 | AG19: 0 | AH19: 0
A20: ACR196 | B20: CAOD5027 | C20: 1 | D20: ODS | E20: COP | F20: 41262 | G20: 41579 | H20: 2013 | I20: RR ACR 2013 | J20: RapRec Refrigerants, Inc. | K20: First Environment of California, Inc. | L20: CAOD5027-A | M20: https://greentrace.ice.com/acr/projects/registry/ACR_REGISTRY/project/P2423C9VKP26 | N20: 56124 | O20: ambiguous | P20: 2011 | Q20: 0.9671 | R20: 0.001 | S20: 0 | T20: 0.0319 | U20: 0 | V20: 0 | W20: 0 | X20: 0 | Z20: Discrepancy: Project listing document just lists refrigerants, and treating the ODPR numbers that way replicates the crediting calculation. However, there are HCFCs in the ODS destroyed table reported in the OPDR. Since they are very small quantities, and don't end up affecting the attribution ratios, we ignore here. | AA20: 0.9675 | AB20: 0.001 | AC20: 0 | AD20: 0.0315 | AE20: 0 | AF20: 0 | AG20: 0 | AH20: 0
A21: ACR198 | B21: CAOD5031 | C21: 1 | D21: ODS | E21: COP | F21: 41615 | G21: 41623 | H21: 2013 | I21: Wabashco Clean Sweep 2 | J21: Wabashco, LLC | K21: Ruby Canyon Engineering, Inc. | L21: CAOD5031-A | M21: https://greentrace.ice.com/acr/projects/registry/ACR_REGISTRY/project/P2423C9VPH22 | N21: 88044 | O21: ref | P21: 2011 | Q21: 0.0002 | R21: 0.9996 | S21: 0 | T21: 0.0001 | U21: 0 | V21: 0.0002 | W21: 0 | X21: 0 | AA21: 0.0002 | AB21: 0.9995 | AC21: 0 | AD21: 0.0001 | AE21: 0 | AF21: 0.0002 | AG21: 0 | AH21: 0
A22: ACR206 | B22: CAOD5052 | C22: 1 | D22: ODS | E22: COP | F22: 41743 | G22: 41751 | H22: 2014 | I22: 2014-P4 | J22: EOS Climate, Inc. | K22: NSF International | L22: CAOD5052-A | M22: https://greentrace.ice.com/acr/projects/registry/ACR_REGISTRY/project/P2323C9VXL25 | N22: 71825 | O22: ref | P22: 2011 | Q22: 0 | R22: 0.9995 | S22: 0 | T22: 0 | U22: 0.0004 | V22: 0.0002 | W22: 0 | X22: 0 | AA22: 0 | AB22: 0.9994 | AC22: 0 | AD22: 0 | AE22: 0.0004 | AF22: 0.0002 | AG22: 0 | AH22: 0
A23: ACR208 | B23: CAOD5056 | C23: 1 | D23: ODS | E23: COP | F23: 41641 | G23: 41782 | H23: 2014 | I23: RR ACR 2014 | J23: RapRec Refrigerants, Inc. | K23: First Environment of California, Inc. | L23: CAOD5056-A | M23: https://greentrace.ice.com/acr/projects/registry/ACR_REGISTRY/project/P2323C9VKP25 | N23: 315794 | O23: ref | P23: 2011 | Q23: 0.5672 | R23: 0.4287 | S23: 0 | T23: 0.0034 | U23: 0.0004 | V23: 0.0004 | W23: 0 | X23: 0 | AA23: 0.5639 | AB23: 0.4319 | AC23: 0 | AD23: 0.0033 | AE23: 0.0004 | AF23: 0.0005 | AG23: 0 | AH23: 0
A24: ACR213 | B24: CAOD5068 | C24: 1 | D24: ODS | E24: COP | F24: 42074 | G24: 42087 | H24: 2015 | I24: EOS ACR 213 | J24: EOS Climate, Inc. | K24: SES, Inc. | L24: CAOD5068-A | M24: https://greentrace.ice.com/acr/projects/registry/ACR_REGISTRY/project/P2423C9VXM22 | N24: 127664 | O24: ref | P24: 2011 | Q24: 0 | R24: 0.9995 | S24: 0 | T24: 0.0001 | U24: 0.0004 | V24: 0 | W24: 0 | X24: 0 | AA24: =(AA7*($C19/$C7))/$C19 -> 0.1908 | AB24: =(AB7*($C19/$C7))/$C19 -> 0.6725 | AC24: =(AC7*($C19/$C7))/$C19 -> 0 | AD24: =(AD7*($C19/$C7))/$C19 -> 0.098 | AE24: =(AE7*($C19/$C7))/$C19 -> 0.0221 | AF24: =(AF7*($C19/$C7))/$C19 -> 0.0166 | AG24: =(AG7*($C19/$C7))/$C19 -> 0 | AH24: =(AH7*($C19/$C7))/$C19 -> 0
A25: ACR214 | B25: CAOD5069 | C25: 1 | D25: ODS | E25: COP | F25: 42128 | G25: 42144 | H25: 2015 | I25: EOS ACR 214 | J25: EOS Climate, Inc. | K25: SES, Inc. | L25: CAOD5069-A | M25: https://greentrace.ice.com/acr/projects/registry/ACR_REGISTRY/project/P2323C9VY923 | N25: 145580 | O25: ref | P25: 2011 | Q25: 0.0002 | R25: 0.9995 | S25: 0 | T25: 0 | U25: 0.0002 | V25: 0.0001 | W25: 0 | X25: 0 | AA25: 0.0002 | AB25: 0.9994 | AC25: 0 | AD25: 0 | AE25: 0.0002 | AF25: 0.0002 | AG25: 0 | AH25: 0
A26: ACR221 | B26: CAOD5070 | C26: 1 | D26: ODS | E26: COP | F26: 41810 | G26: 41822 | H26: 2014 | I26: Wabashco Clean Sweep 3 | J26: Wabashco, LLC | K26: Ruby Canyon Engineering, Inc. | L26: CAOD5070-A | M26: https://greentrace.ice.com/acr/projects/registry/ACR_REGISTRY/project/P2423C9VPH23 | N26: 112378 | O26: ref | P26: 2011 | Q26: 0.0004 | R26: 0.9993 | S26: 0 | T26: 0.0003 | U26: 0 | V26: 0 | W26: 0 | X26: 0 | AA26: 0.0004 | AB26: 0.9993 | AC26: 0 | AD26: 0.0003 | AE26: 0 | AF26: 0 | AG26: 0 | AH26: 0
A27: ACR225 | B27: CAOD5099 | C27: 1 | D27: ODS | E27: COP | F27: 42027 | G27: 42048 | H27: 2015 | I27: Wabashco Clean Sweep 4 | J27: Wabashco, LLC | K27: Ruby Canyon Engineering, Inc. | L27: CAOD5099-A | M27: https://greentrace.ice.com/acr/projects/registry/ACR_REGISTRY/project/P2323C9VPJ25 | N27: 110003 | O27: ref | P27: 2011 | Q27: 0.0001 | R27: 0.9999 | S27: 0 | T27: 0 | U27: 0 | V27: 0 | W27: 0 | X27: 0 | AA27: 0.0001 | AB27: 0.9999 | AC27: 0 | AD27: 0 | AE27: 0 | AF27: 0 | AG27: 0 | AH27: 0
A28: ACR240 | B28: CAOD5140 | C28: 1 | D28: ODS | E28: COP | F28: 42276 | G28: 42295 | H28: 2015 | I28: EOS ACR 240 | J28: EOS Climate, Inc. | K28: SES, Inc. | L28: CAOD5140-A | M28: https://greentrace.ice.com/acr/projects/registry/ACR_REGISTRY/project/P2423C9VWU24 | N28: 129700 | O28: ref | P28: 2014 | Q28: 0 | R28: 0.9998 | S28: 0 | T28: 0 | U28: 0.0001 | V28: 0 | W28: 0 | X28: 0 | AA28: 0 | AB28: 0.9998 | AC28: 0 | AD28: 0 | AE28: 0.0001 | AF28: 0 | AG28: 0 | AH28: 0
A29: ACR244 | B29: CAOD5177 | C29: 1 | D29: ODS | E29: COP | F29: 42094 | G29: 42117 | H29: 2015 | I29: Wabashco Clean Sweep 5 | J29: Wabashco, LLC | K29: Ruby Canyon Engineering, Inc. | L29: CAOD5177-A | M29: https://greentrace.ice.com/acr/projects/registry/ACR_REGISTRY/project/P2323C9VPH24 | N29: 57589 | O29: ref | P29: 2014 | Q29: 0.0025 | R29: 0.9973 | S29: 0 | T29: 0.0001 | U29: 0.0001 | V29: 0 | W29: 0 | X29: 0 | AA29: 0.0025 | AB29: 0.9973 | AC29: 0 | AD29: 0.0001 | AE29: 0.0001 | AF29: 0 | AG29: 0 | AH29: 0
A30: ACR252 | B30: CAOD5188 | C30: 1 | D30: ODS | E30: COP | F30: 42311 | G30: 42327 | H30: 2015 | I30: EOS ACR 252 | J30: EOS Climate, Inc. | K30: SES, Inc. | L30: CAOD5188-A | M30: https://greentrace.ice.com/acr/projects/registry/ACR_REGISTRY/project/P2323C9VXH23 | N30: 140736 | O30: ref | P30: 2014 | Q30: 0 | R30: 0.9998 | S30: 0 | T30: 0 | U30: 0.0001 | V30: 0 | W30: 0 | X30: 0 | AA30: 0 | AB30: 0.9998 | AC30: 0 | AD30: 0 | AE30: 0.0001 | AF30: 0 | AG30: 0 | AH30: 0
A31: ACR253 | B31: CAOD5189 | C31: 1 | D31: ODS | E31: COP | F31: 42345 | G31: 42359 | H31: 2015 | I31: EOS ACR 253 | J31: EOS Climate, Inc. | K31: SES, Inc. | L31: CAOD5189-A | M31: https://greentrace.ice.com/acr/projects/registry/ACR_REGISTRY/project/P2423C9VXJ24 | N31: 135017 | O31: ref | P31: 2014 | Q31: 0 | R31: 0.9997 | S31: 0 | T31: 0 | U31: 0.0002 | V31: 0 | W31: 0 | X31: 0 | AA31: 0 | AB31: 0.9997 | AC31: 0 | AD31: 0 | AE31: 0.0002 | AF31: 0 | AG31: 0 | AH31: 0
A32: ACR254 | B32: CAOD5191 | C32: 1 | D32: ODS | E32: COP | F32: 42266 | G32: 42275 | H32: 2015 | I32: Wabashco Clean Sweep 6 | J32: Wabashco, LLC | K32: Ruby Canyon Engineering, Inc. | L32: CAOD5191-A | M32: https://greentrace.ice.com/acr/projects/registry/ACR_REGISTRY/project/P2323C9VN225 | N32: 39036 | O32: ref | P32: 2014 | Q32: 0 | R32: 0.9983 | S32: 0 | T32: 0 | U32: 0.0017 | V32: 0 | W32: 0 | X32: 0 | AA32: 0 | AB32: 0.9983 | AC32: 0 | AD32: 0 | AE32: 0.0017 | AF32: 0 | AG32: 0 | AH32: 0
A33: ACR271 | B33: CAOD5211 | C33: 1 | D33: ODS | E33: COP | F33: 42382 | G33: 42393 | H33: 2016 | I33: EOS ACR 271 | J33: EOS Climate, Inc. | K33: Ruby Canyon Engineering, Inc. | L33: CAOD5211-A | M33: https://greentrace.ice.com/acr/projects/registry/ACR_REGISTRY/project/P2323C9VXJ25 | N33: 124882 | O33: ref | P33: 2014 | Q33: 0 | R33: 0.9996 | S33: 0 | T33: 0 | U33: 0.0001 | V33: 0.0002 | W33: 0 | X33: 0 | AA33: 0 | AB33: 0.9995 | AC33: 0 | AD33: 0 | AE33: 0.0002 | AF33: 0.0003 | AG33: 0 | AH33: 0
A34: ACR275 | B34: CAOD5215 | C34: 1 | D34: ODS | E34: COP | F34: 42367 | G34: 42381 | H34: 2016 | I34: Wabashco Clean Sweep 7 | J34: Wabashco, LLC | K34: Ruby Canyon Engineering, Inc. | L34: CAOD5215-A | M34: https://greentrace.ice.com/acr/projects/registry/ACR_REGISTRY/project/P2423C9VN322 | N34: 116836 | O34: ref | P34: 2014 | Q34: 0.0001 | R34: 0.9984 | S34: 0 | T34: 0 | U34: 0.0015 | V34: 0 | W34: 0 | X34: 0 | AA34: 0.0001 | AB34: 0.9984 | AC34: 0 | AD34: 0 | AE34: 0.0015 | AF34: 0 | AG34: 0 | AH34: 0
A35: ACR285 | B35: CAOD5216 | C35: 1 | D35: ODS | E35: COP | F35: 42328 | G35: 42332 | H35: 2015 | I35: EOS ACR 285 | J35: EOS Climate, Inc. | K35: SES, Inc. | L35: CAOD5216-A | M35: https://greentrace.ice.com/acr/projects/registry/ACR_REGISTRY/project/P2423C9VY923 | N35: 45663 | O35: ref | P35: 2014 | Q35: 0.9638 | R35: 0.0075 | S35: 0 | T35: 0.0287 | U35: 0 | V35: 0 | W35: 0 | X35: 0 | AA35: 0.964 | AB35: 0.0076 | AC35: 0 | AD35: 0.0283 | AE35: 0 | AF35: 0 | AG35: 0 | AH35: 0
A36: ACR311 | B36: CAOD5261 | C36: 1 | D36: ODS | E36: COP | F36: 42466 | G36: 42473 | H36: 2016 | I36: EOS ACR 311 | J36: EOS Climate, Inc. | K36: Ruby Canyon Engineering, Inc. | L36: CAOD5261-A | M36: https://greentrace.ice.com/acr/projects/registry/ACR_REGISTRY/project/P2323C9VXK23 | N36: 107264 | O36: ref | P36: 2014 | Q36: 0.0002 | R36: 0.96 | S36: 0 | T36: 0 | U36: 0.0335 | V36: 0.0063 | W36: 0 | X36: 0 | AA36: 0.0002 | AB36: 0.9578 | AC36: 0 | AD36: 0 | AE36: 0.0341 | AF36: 0.0079 | AG36: 0 | AH36: 0
... A39: ACR315 | B39: CAOD5277 | C39: 1 | D39: ODS | E39: COP | F39: 42583 | G39: 42594 | H39: 2016 | I39: EOS ACR 315 | J39: EOS Climate, Inc. | K39: Ruby Canyon Engineering, Inc. | L39: CAOD5277-A | M39: https://greentrace.ice.com/acr/projects/registry/ACR_REGISTRY/project/P2423C9VY825 | N39: 86839 | O39: ref | P39: 2014 | Q39: 0.003 | R39: 0.9772 | S39: 0 | T39: 0 | U39: 0.0198 | V39: 0 | W39: 0 | X39: 0 | AA39: 0.0029 | AB39: 0.9768 | AC39: 0.0001 | AD39: 0 | AE39: 0.0202 | AF39: 0 | AG39: 0 | AH39: 0
A40: ACR316 | B40: CAOD5278 | C40: 1 | D40: ODS | E40: COP | F40: 42601 | G40: 42617 | H40: 2016 | I40: EOS ACR 316 | J40: EOS Climate, Inc. | K40: Ruby Canyon Engineering, Inc. | L40: CAOD5278-A | M40: https://greentrace.ice.com/acr/projects/registry/ACR_REGISTRY/project/P2423C9VY826 | N40: 104897 | O40: ref | P40: 2014 | Q40: 0.0006 | R40: 0.9941 | S40: 0 | T40: 0 | U40: 0.0028 | V40: 0.0024 | W40: 0 | X40: 0 | AA40: =(AA20*($C35/$C20))/$C35 -> 0.9675 | AB40: =(AB20*($C35/$C20))/$C35 -> 0.001 | AC40: =(AC20*($C35/$C20))/$C35 -> 0 | AD40: =(AD20*($C35/$C20))/$C35 -> 0.0315 | AE40: =(AE20*($C35/$C20))/$C35 -> 0 | AF40: =(AF20*($C35/$C20))/$C35 -> 0 | AG40: =(AG20*($C35/$C20))/$C35 -> 0 | AH40: =(AH20*($C35/$C20))/$C35 -> 0
A41: ACR343 | B41: CAOD5343 | C41: 1 | D41: ODS | E41: COP | F41: 42559 | G41: 42582 | H41: 2016 | I41: Wabashco Clean Sweep 9 | J41: Wabashco, LLC | K41: SCS Global Services | L41: CAOD5343-A | M41: https://greentrace.ice.com/acr/projects/registry/ACR_REGISTRY/project/P2323C9VP523 | N41: 93298 | O41: ref | P41: 2014 | Q41: 0.003 | R41: 0.9895 | S41: 0 | T41: 0.0001 | U41: 0.0071 | V41: 0.0002 | W41: 0 | X41: 0 | AA41: 0.003 | AB41: 0.9893 | AC41: 0 | AD41: 0.0001 | AE41: 0.0072 | AF41: 0.0003 | AG41: 0 | AH41: 0
A42: ACR350 | B42: CAOD5350 | C42: 1 | D42: ODS | E42: COP | F42: 42592 | G42: 42595 | H42: 2016 | I42: Tradewater ODS 1 | J42: Tradewater, LLC | K42: Ruby Canyon Engineering, Inc. | L42: CAOD5350-A | M42: https://greentrace.ice.com/acr/projects/registry/ACR_REGISTRY/project/P2423C9VMB22 | N42: 116741 | O42: ref | P42: 2014 | Q42: 0 | R42: 0.9999 | S42: 0 | T42: 0 | U42: 0 | V42: 0 | W42: 0 | X42: 0 | AA42: 0 | AB42: 0.9999 | AC42: 0 | AD42: 0 | AE42: 0 | AF42: 0 | AG42: 0 | AH42: 0
A43: ACR351 | B43: CAOD5351 | C43: 1 | D43: ODS | E43: COP | F43: 42636 | G43: 42641 | H43: 2016 | I43: EOS ACR 351 | J43: EOS Climate, Inc. | K43: SES, Inc. | L43: CAOD5351-A | M43: https://greentrace.ice.com/acr/projects/registry/ACR_REGISTRY/project/P2423C9VVY23 | N43: 28562 | O43: ref | P43: 2014 | Q43: 0.9933 | R43: 0.0005 | S43: 0 | T43: 0.0062 | U43: 0 | V43: 0 | W43: 0 | X43: 0 | AA43: 0.9933 | AB43: 0.0005 | AC43: 0 | AD43: 0.0062 | AE43: 0 | AF43: 0 | AG43: 0 | AH43: 0
A44: ACR352 | B44: CAOD5352 | C44: 1 | D44: ODS | E44: COP | F44: 42669 | G44: 42675 | H44: 2016 | I44: EOS ACR 352 | J44: EOS Climate, Inc. | K44: SES, Inc. | L44: CAOD5352-A | M44: https://greentrace.ice.com/acr/projects/registry/ACR_REGISTRY/project/P2323C9VVZ22 | N44: 68637 | O44: ref | P44: 2014 | Q44: 0.3579 | R44: 0.0009 | S44: 0 | T44: 0.0018 | U44: 0.6394 | V44: 0 | W44: 0 | X44: 0 | AA44: 0.3503 | AB44: 0.0009 | AC44: 0 | AD44: 0.0017 | AE44: 0.647 | AF44: 0 | AG44: 0 | AH44: 0
A45: ACR354 | B45: CAOD5354 | C45: 1 | D45: ODS | E45: COP | F45: 42628 | G45: 42634 | H45: 2016 | I45: Tradewater ODS 2 | J45: Tradewater, LLC | K45: Ruby Canyon Engineering, Inc. | L45: CAOD5354-A | M45: https://greentrace.ice.com/acr/projects/registry/ACR_REGISTRY/project/P2323C9VLZ24 | N45: 103357 | O45: ref | P45: 2014 | Q45: 0 | R45: 0.99 | S45: 0 | T45: 0 | U45: 0.01 | V45: 0 | W45: 0 | X45: 0 | AA45: 0 | AB45: 0.9898 | AC45: 0 | AD45: 0 | AE45: 0.0102 | AF45: 0 | AG45: 0 | AH45: 0
A46: ACR356 | B46: CAOD5356 | C46: 1 | D46: ODS | E46: COP | F46: 42706 | G46: 42732 | H46: 2016 | I46: EOS ACR 356 | J46: EOS Climate, Inc. | K46: SES, Inc. | L46: CAOD5356-A | M46: https://greentrace.ice.com/acr/projects/registry/ACR_REGISTRY/project/P2323C9VVZ23 | N46: 110720 | O46: ref | P46: 2014 | Q46: 0.4326 | R46: 0.5313 | S46: 0 | T46: 0.0163 | U46: 0.0197 | V46: 0.0002 | W46: 0 | X46: 0 | AA46: 0.4294 | AB46: 0.5343 | AC46: 0 | AD46: 0.016 | AE46: 0.0202 | AF46: 0.0002 | AG46: 0 | AH46: 0
A47: ACR357 | B47: CAOD5357 | C47: 1 | D47: ODS | E47: COP | F47: 42741 | G47: 42766 | H47: 2017 | I47: EOS ACR 357 | J47: EOS Climate, Inc. | K47: SES, Inc. | L47: CAOD5357-A | M47: https://greentrace.ice.com/acr/projects/registry/ACR_REGISTRY/project/P2423C9VW223 | N47: 84131 | O47: ref | P47: 2014 | Q47: 0.3455 | R47: 0.5983 | S47: 0 | T47: 0.045 | U47: 0.0112 | V47: 0 | W47: 0 | X47: 0 | AA47: 0.3429 | AB47: 0.6016 | AC47: 0 | AD47: 0.044 | AE47: 0.0115 | AF47: 0 | AG47: 0 | AH47: 0
...

Sheet template_lb
C1: Mass ODS (lb) | D1: CFC-11 (mass%) | E1: CFC-12 (mass%) | F1: CFC-13 (mass%) | G1: CFC-113 (mass%) | H1: CFC-114 (mass%) | I1: CFC-115 (mass%) | J1: HCFC-22 (mass%) | K1: HCFC-141b (mass%)
B2: 1 | C2: 6570 | D2: 0.18 | E2: 77.9 | F2: 0 | G2: 0.07 | H2: 5.11 | I2: 4.7 | J2: 0 | K2: 0
B3: 2 | C3: 5700 | D3: 0.3 | E3: 82.23 | F3: 0 | G3: 0.04 | H3: 1.11 | I3: 5.56 | J3: 0 | K3: 0
B4: 3 | C4: 4186 | D4: 0.27 | E4: 93.49 | F4: 0 | G4: 0.41 | H4: 0.64 | I4: 1.49 | J4: 0 | K4: 0
B5: 4 | C5: 7290 | D5: 0.01 | E5: 0.1 | F5: 0 | G5: 99.78 | H5: 0.01 | I5: 0.02 | J5: 0 | K5: 0
B6: 5
B72: 114329 | C72: =sum(D72:K72) -> 22180.938 | D72: =SUMPRODUCT((D2:D70/100)*$C2:$C70) -> 40.9572 | E72: =SUMPRODUCT((E2:E70/100)*$C2:$C70) -> 13725.921 | F72: =SUMPRODUCT((F2:F70/100)*$C2:$C70) -> 0 | G72: =SUMPRODUCT((G2:G70/100)*$C2:$C70) -> 7298.0036 | H72: =SUMPRODUCT((H2:H70/100)*$C2:$C70) -> 426.5164 | I72: =SUMPRODUCT((I2:I70/100)*$C2:$C70) -> 689.5394 | J72: =SUMPRODUCT((J2:J70/100)*$C2:$C70) -> 0 | K72: =SUMPRODUCT((K2:K70/100)*$C2:$C70) -> 0
A73: Q_refr,i | B73: mass eligible ods sent for destruction (mtODS) | C73: =sum(D73:K73) -> 10.061052 | D73: =D72*0.00045359 -> 0.018577776 | E73: =E72*0.00045359 -> 6.2259407 | F73: =F72*0.00045359 -> 0 | G73: =G72*0.00045359 -> 3.3103015 | H73: =H72*0.00045359 -> 0.19346357 | I73: =I72*0.00045359 -> 0.31276818 | J73: =J72*0.00045359 -> 0 | K73: =K72*0.00045359 -> 0
B75: project baseline emissions (mtco2e) | C75: 15105
A76: BE (Eq 5.2) | B76: project baseline emissions (mtCO2e) | C76: =sum(C78) -> 85523.293
A78: BE_refr (Eq 5.3) | B78: mass baseline emissions from regrigerant ODS (mtCO2e) | C78: =sum(D78:K78) -> 85523.293 | D78: =D73*D79*D80 -> 78.53755 | E78: =E73*E79*E80 -> 64469.616 | F78: =F73*F79*F80 -> 0 | G78: =G73*G79*G80 -> 18060.012 | H78: =H73*H79*H80 -> 1509.0159 | I78: =I73*I79*I80 -> 1406.1119 | J78: =J73*J79*J80 -> 0 | K78: =K73*K79*K80 -> 0
A79: ER_refr,i (Table B.1) | B79: 10-year cumulative emission rate for refrigerant ODS (..) | D79: 0.89 | E79: 0.95 | F79: 0.61 | G79: 0.89 | H79: 0.78 | I79: 0.61
A80: GWP_i (Table B.1) | B80: GWP ODS (mtCO2e / mtODS) | D80: 4750 | E80: 10900 | F80: 14400 | G80: 6130 | H80: 10000 | I80: 7370 | J80: 1810 | K80: 725
B82: project emissions (mtco2e) | C82: 5540
A83: PE (Eq 5.5) | B83: project emissions (mtco2e) | C83: =sum(C85, C88) -> 5562.5978
A85: Sub_ref (Eq 5.6) | B85: total ghg emissions from sub refrigerant (mtCO2e) | C85: =sum(D85:K85) -> 5487.1399 | D85: =D73*D86 -> 4.1428441 | E85: =E73*E86 -> 4270.9953 | F85: =F73*F86 -> 0 | G85: =G73*G86 -> 728.26632 | H85: =H73*H86 -> 127.4925 | I85: =I73*I86 -> 356.24295 | J85: =J73*J86 -> 0 | K85: =K73*K86 -> 0
A86: SE_i | B86: substitute emissions (tco2e / tODS) | D86: 223 | E86: 686 | F86: 7144 | G86: 220 | H86: 659 | I86: 1139
A88: Tr + Dest (Eq 5.8) | B88: Total GHG emissions from transport of ODS (mtCO2e) | C88: =C89*C90 -> 75.457888 | D88: =D89*$C90 -> 0.13933332 | E88: =E89*$C90 -> 46.694555 | F88: =F89*$C90 -> 0 | G88: =G89*$C90 -> 24.827261 | H88: =H89*$C90 -> 1.4509768 | I88: =I89*$C90 -> 2.3457613 | J88: =J89*$C90 -> 0 | K88: =K89*$C90 -> 0
A89: Q_totalODS | B89: total mass of ods sent for destruction | C89: =C73 -> 10.061052 | D89: =D73 -> 0.018577776 | E89: =E73 -> 6.2259407 | F89: =F73 -> 0 | G89: =G73 -> 3.3103015 | H89: =H73 -> 0.19346357 | I89: =I73 -> 0.31276818 | J89: =J73 -> 0 | K89: =K73 -> 0
A90: EF_T&D | B90: default emission factor for refrigernat or extracted ODS blowing agent | C90: 7.5
B93: total reductions (mtco2e) | C93: 79565
B94: total reductions (mtco2e) | C94: =C78-C85-C88 -> 79960.695 | D94: =D78-D85-D88 -> 74.255372 | E94: =E78-E85-E88 -> 60151.926 | F94: =F78-F85-F88 -> 0 | G94: =G78-G85-G88 -> 17306.918 | H94: =H78-H85-H88 -> 1380.0724 | I94: =I78-I85-I88 -> 1047.5232 | J94: =J78-J85-J88 -> 0 | K94: =K78-K85-K88 -> 0
B95: credit replication diff (%) | C95: =abs(C94-C93)/C93 -> 0.004973229
B96: contribution ratio — project approach | C96: =sum(D96:K96) -> 1 | D96: =D94/$C94 -> 0.00092864841 | E96: =E94/$C94 -> 0.75226867 | F96: =F94/$C94 -> 0 | G96: =G94/$C94 -> 0.21644282 | H96: =H94/$C94 -> 0.017259385 | I96: =I94/$C94 -> 0.013100476 | J96: =J94/$C94 -> 0 | K96: =K94/$C94 -> 0
B97: contribution ratio — atmosphere approach | C97: =sum(D97:K97) -> 1 | D97: =(D78*($C93/$C78))/$C93 -> 0.00091831765 | E97: =(E78*($C93/$C78))/$C93 -> 0.75382523 | F97: =(F78*($C93/$C78))/$C93 -> 0 | G97: =(G78*($C93/$C78))/$C93 -> 0.21117068 | H97: =(H78*($C93/$C78))/$C93 -> 0.017644502 | I97: =(I78*($C93/$C78))/$C93 -> 0.016441274 | J97: =(J78*($C93/$C78))/$C93 -> 0 | K97: =(K78*($C93/$C78))/$C93 -> 0

Sheet template_kg
C1: Mass ODS (kg) | D1: CFC-11 (mass%) | E1: CFC-12 (mass%) | F1: CFC-13 (mass%) | G1: CFC-113 (mass%) | H1: CFC-114 (mass%) | I1: CFC-115 (mass%) | J1: HCFC-22 (mass%) | K1: HCFC-141b (mass%)
B2: 1 | C2: 13221 | D2: 16.25 | E2: 66.57 | F2: 0 | G2: 0 | H2: 3.52 | I2: 1.22 | J2: 0 | K2: 0
B3: 2 | C3: 9904 | D3: 0.02 | E3: 97.01 | F3: 0 | G3: 0 | H3: 0 | I3: 0.01 | J3: 0 | K3: 0
B4: 3 | C4: 12162 | D4: 0.05 | E4: 98.86 | F4: 0 | G4: 0.01 | H4: 0 | I4: 0.01 | J4: 0 | K4: 0
B5: 4
B6: 5
B23: mass eligible ods sent for destruction (kgODS) | C23: =sum(D23:K23) -> 33219.016 | D23: =SUMPRODUCT((D2:D21/100)*$C2:$C21) -> 2156.4743 | E23: =SUMPRODUCT((E2:E21/100)*$C2:$C21) -> 30432.443 | F23: =SUMPRODUCT((F2:F21/100)*$C2:$C21) -> 0 | G23: =SUMPRODUCT((G2:G21/100)*$C2:$C21) -> 1.2162 | H23: =SUMPRODUCT((H2:H21/100)*$C2:$C21) -> 465.3792 | I23: =SUMPRODUCT((I2:I21/100)*$C2:$C21) -> 163.5028 | J23: =SUMPRODUCT((J2:J21/100)*$C2:$C21) -> 0 | K23: =SUMPRODUCT((K2:K21/100)*$C2:$C21) -> 0
A24: Q_refr,i | B24: mass eligible ods sent for destruction (mtODS) | C24: =sum(D24:K24) -> 33.219016 | D24: =D23*0.001 -> 2.1564743 | E24: =E23*0.001 -> 30.432443 | F24: =F23*0.001 -> 0 | G24: =G23*0.001 -> 0.0012162 | H24: =H23*0.001 -> 0.4653792 | I24: =I23*0.001 -> 0.1635028 | J24: =J23*0.001 -> 0 | K24: =K23*0.001 -> 0
B26: project baseline emissions (mtco2e) | C26: 306517
A27: BE (Eq 5.2) | B27: project baseline emissions (mtCO2e) | C27: =sum(C29) -> 328616.1
A29: BE_refr (Eq 5.3) | B29: mass baseline emissions from regrigerant ODS (mtCO2e) | C29: =sum(D29:K29) -> 328616.1 | D29: =D24*D31*D30 -> 9116.4951 | E29: =E24*E31*E30 -> 315127.95 | F29: =F24*F31*F30 -> 0 | G29: =G24*G31*G30 -> 6.6352223 | H29: =H24*H31*H30 -> 3629.9578 | I29: =I24*I31*I30 -> 735.05954 | J29: =J24*J31*J30 -> 0 | K29: =K24*K31*K30 -> 0
A30: GWP_i (Table 5.1) | B30: GWP ODS (mtCO2e / mtODS) | D30: 4750 | E30: 10900 | F30: 14400 | G30: 6130 | H30: 10000 | I30: 7370 | J30: 1810 | K30: 725
A31: ER_refr,i (Table 5.2) | B31: 10-year cumulative emission rate for refrigerant ODS (..) | D31: 0.89 | E31: 0.95 | F31: 0.61 | G31: 0.89 | H31: 0.78 | I31: 0.61
B33: project emissions (mtco2e) | C33: 22100
A34: PE (Eq 5.5) | B34: project emissions (mtco2e) | C34: =sum(C36,C39) -> 22099.875
A36: Sub_ref (Eq 5.6) | B36: total ghg emissions from sub refrigerant (mtCO2e) | C36: =sum(D36:K36) -> 21850.732 | D36: =D24*D37 -> 480.89377 | E36: =E24*E37 -> 20876.656 | F36: =F24*F37 -> 0 | G36: =G24*G37 -> 0.267564 | H36: =H24*H37 -> 306.68489 | I36: =I24*I37 -> 186.22969 | J36: =J24*J37 -> 0 | K36: =K24*K37 -> 0
A37: SE_i (Table 5.4) | B37: substitute emissions (tco2e / tODS) | D37: 223 | E37: 686 | F37: 7144 | G37: 220 | H37: 659 | I37: 1139
A39: Tr + Dest (Eq 5.8) | B39: Total GHG emissions from transport of ODS (mtCO2e) | C39: =C40*C41 -> 249.14262 | D39: =D40*$C41 -> 16.173557 | E39: =E40*$C41 -> 228.24332 | F39: =F40*$C41 -> 0 | G39: =G40*$C41 -> 0.0091215 | H39: =H40*$C41 -> 3.490344 | I39: =I40*$C41 -> 1.226271 | J39: =J40*$C41 -> 0 | K39: =K40*$C41 -> 0
A40: Q_totalODS | B40: total mass of ods sent for destruction | C40: =C24 -> 33.219016 | D40: =D24 -> 2.1564743 | E40: =E24 -> 30.432443 | F40: =F24 -> 0 | G40: =G24 -> 0.0012162 | H40: =H24 -> 0.4653792 | I40: =I24 -> 0.1635028 | J40: =J24 -> 0 | K40: =K24 -> 0
A41: EF_T&D | B41: default emission factor for refrigernat or extracted ODS blowing agent | C41: 7.5
B44: total reductions (mtco2e) | C44: 328617
B45: total reductions (mtco2e) | C45: =C29-C36-C39 -> 306516.22 | D45: =D29-D36-D39 -> 8619.4278 | E45: =E29-E36-E39 -> 294023.05 | F45: =F29-F36-F39 -> 0 | G45: =G29-G36-G39 -> 6.3585368 | H45: =H29-H36-H39 -> 3319.7825 | I45: =I29-I36-I39 -> 547.60358 | J45: =J29-J36-J39 -> 0 | K45: =K29-K36-K39 -> 0
B46: credit replication diff (%) | C46: =abs(C45-C44)/C44 -> 0.067253905
B47: contribution ratio | C47: =sum(D47:K47) -> 1 | D47: =D45/$C45 -> 0.028120625 | E47: =E45/$C45 -> 0.9592414 | F47: =F45/$C45 -> 0 | G47: =G45/$C45 -> 2.0744536e-05 | H47: =H45/$C45 -> 0.010830691 | I47: =I45/$C45 -> 0.0017865403 | J47: =J45/$C45 -> 0 | K47: =K45/$C45 -> 0
B48: contribution ratio — atmosphere approach | C48: =sum(D48:K48) -> 1 | D48: =(D29*($C44/$C29))/$C44 -> 0.027742083 | E48: =(E29*($C44/$C29))/$C44 -> 0.9589547 | F48: =(F29*($C44/$C29))/$C44 -> 0 | G48: =(G29*($C44/$C29))/$C44 -> 2.019141e-05 | H48: =(H29*($C44/$C29))/$C44 -> 0.011046196 | I48: =(I29*($C44/$C29))/$C44 -> 0.0022368336 | J48: =(J29*($C44/$C29))/$C44 -> 0 | K48: =(K29*($C44/$C29))/$C44 -> 0

Sheet weighted_avgs
B1: CFC-11 | C1: CFC-12 | D1: CFC-13 | E1: CFC-113 | F1: CFC-114 | G1: CFC-115 | H1: HCFC-22 | I1: HCFC-141b
A3: COP - ratio project approach | B3: =SUMPRODUCT(ods_project_ids!$N2:$N216,ods_project_ids!Q2:Q216)/SUM(ods_project_ids!$N2:$N216) -> 0.16841779 | C3: =SUMPRODUCT(ods_project_ids!$N2:$N216,ods_project_ids!R2:R216)/SUM(ods_project_ids!$N2:$N216) -> 0.7258349 | D3: =SUMPRODUCT(ods_project_ids!$N2:$N216,ods_project_ids!S2:S216)/SUM(ods_project_ids!$N2:$N216) -> 0.00053785558 | E3: =SUMPRODUCT(ods_project_ids!$N2:$N216,ods_project_ids!T2:T216)/SUM(ods_project_ids!$N2:$N216) -> 0.061297343 | F3: =SUMPRODUCT(ods_project_ids!$N2:$N216,ods_project_ids!U2:U216)/SUM(ods_project_ids!$N2:$N216) -> 0.037637904 | G3: =SUMPRODUCT(ods_project_ids!$N2:$N216,ods_project_ids!V2:V216)/SUM(ods_project_ids!$N2:$N216) -> 0.0041980319 | H3: =SUMPRODUCT(ods_project_ids!$N2:$N216,ods_project_ids!W2:W216)/SUM(ods_project_ids!$N2:$N216) -> -3.1320514e-10 | I3: =SUMPRODUCT(ods_project_ids!$N2:$N216,ods_project_ids!X2:X216)/SUM(ods_project_ids!$N2:$N216) -> 0
A4: COP - ratio atmosphere approach | B4: =SUMPRODUCT(ods_project_ids!$N2:$N216,ods_project_ids!AA2:AA216)/SUM(ods_project_ids!$N2:$N216) -> 0.16863733 | C4: =SUMPRODUCT(ods_project_ids!$N2:$N216,ods_project_ids!AB2:AB216)/SUM(ods_project_ids!$N2:$N216) -> 0.72086085 | D4: =SUMPRODUCT(ods_project_ids!$N2:$N216,ods_project_ids!AC2:AC216)/SUM(ods_project_ids!$N2:$N216) -> 0.0018946632 | E4: =SUMPRODUCT(ods_project_ids!$N2:$N216,ods_project_ids!AD2:AD216)/SUM(ods_project_ids!$N2:$N216) -> 0.060337314 | F4: =SUMPRODUCT(ods_project_ids!$N2:$N216,ods_project_ids!AE2:AE216)/SUM(ods_project_ids!$N2:$N216) -> 0.038304377 | G4: =SUMPRODUCT(ods_project_ids!$N2:$N216,ods_project_ids!AF2:AF216)/SUM(ods_project_ids!$N2:$N216) -> 0.0051084628 | H4: =SUMPRODUCT(ods_project_ids!$N2:$N216,ods_project_ids!AG2:AG216)/SUM(ods_project_ids!$N2:$N216) -> 0 | I4: =SUMPRODUCT(ods_project_ids!$N2:$N216,ods_project_ids!AH2:AH216)/SUM(ods_project_ids!$N2:$N216) -> 0
A6: ALL - ratio project approach | B6: =SUMPRODUCT(ods_project_ids!$N2:$N303, ods_project_ids!Q2:Q303, --(ods_project_ids!$Y2:$Y303<>"yes")) /SUMPRODUCT(ods_project_ids!$N2:$N303, --(ods_project_ids!$Y2:$Y303<>"yes")) -> 0.16576485 | C6: =SUMPRODUCT(ods_project_ids!$N2:$N303, ods_project_ids!R2:R303, --(ods_project_ids!$Y2:$Y303<>"yes")) /SUMPRODUCT(ods_project_ids!$N2:$N303, --(ods_project_ids!$Y2:$Y303<>"yes")) -> 0.74663179 | D6: =SUMPRODUCT(ods_project_ids!$N2:$N303, ods_project_ids!S2:S303, --(ods_project_ids!$Y2:$Y303<>"yes")) /SUMPRODUCT(ods_project_ids!$N2:$N303, --(ods_project_ids!$Y2:$Y303<>"yes")) -> 0.00044114044 | E6: =SUMPRODUCT(ods_project_ids!$N2:$N303, ods_project_ids!T2:T303, --(ods_project_ids!$Y2:$Y303<>"yes")) /SUMPRODUCT(ods_project_ids!$N2:$N303, --(ods_project_ids!$Y2:$Y303<>"yes")) -> 0.050275088 | F6: =SUMPRODUCT(ods_project_ids!$N2:$N303, ods_project_ids!U2:U303, --(ods_project_ids!$Y2:$Y303<>"yes")) /SUMPRODUCT(ods_project_ids!$N2:$N303, --(ods_project_ids!$Y2:$Y303<>"yes")) -> 0.033253961 | G6: =SUMPRODUCT(ods_project_ids!$N2:$N303, ods_project_ids!V2:V303, --(ods_project_ids!$Y2:$Y303<>"yes")) /SUMPRODUCT(ods_project_ids!$N2:$N303, --(ods_project_ids!$Y2:$Y303<>"yes")) -> 0.0036213253 | H6: =SUMPRODUCT(ods_project_ids!$N2:$N303, ods_project_ids!W2:W303, --(ods_project_ids!$Y2:$Y303<>"yes")) /SUMPRODUCT(ods_project_ids!$N2:$N303, --(ods_project_ids!$Y2:$Y303<>"yes")) -> -2.5688578e-10 | I6: =SUMPRODUCT(ods_project_ids!$N2:$N303, ods_project_ids!X2:X303, --(ods_project_ids!$Y2:$Y303<>"yes")) /SUMPRODUCT(ods_project_ids!$N2:$N303, --(ods_project_ids!$Y2:$Y303<>"yes")) -> 0
A7: EA - ratio project approach | B7: =SUMPRODUCT(ods_project_ids!$N217:$N303, ods_project_ids!Q217:Q303, --(ods_project_ids!$Y217:$Y303<>"yes")) /SUMPRODUCT(ods_project_ids!$N217:$N303, --(ods_project_ids!$Y217:$Y303<>"yes")) -> 0.15223209 | C7: =SUMPRODUCT(ods_project_ids!$N217:$N303, ods_project_ids!R217:R303, --(ods_project_ids!$Y217:$Y303<>"yes")) /SUMPRODUCT(ods_project_ids!$N217:$N303, --(ods_project_ids!$Y217:$Y303<>"yes")) -> 0.83364905 | D7: =SUMPRODUCT(ods_project_ids!$N217:$N303, ods_project_ids!S217:S303, --(ods_project_ids!$Y217:$Y303<>"yes")) /SUMPRODUCT(ods_project_ids!$N217:$N303, --(ods_project_ids!$Y217:$Y303<>"yes")) -> 0 | E7: =SUMPRODUCT(ods_project_ids!$N217:$N303, ods_project_ids!T217:T303, --(ods_project_ids!$Y217:$Y303<>"yes")) /SUMPRODUCT(ods_project_ids!$N217:$N303, --(ods_project_ids!$Y217:$Y303<>"yes")) -> 0 | F7: =SUMPRODUCT(ods_project_ids!$N217:$N303, ods_project_ids!U217:U303, --(ods_project_ids!$Y217:$Y303<>"yes")) /SUMPRODUCT(ods_project_ids!$N217:$N303, --(ods_project_ids!$Y217:$Y303<>"yes")) -> 0.013134218 | G7: =SUMPRODUCT(ods_project_ids!$N217:$N303, ods_project_ids!V217:V303, --(ods_project_ids!$Y217:$Y303<>"yes")) /SUMPRODUCT(ods_project_ids!$N217:$N303, --(ods_project_ids!$Y217:$Y303<>"yes")) -> 0.00098159758 | H7: =SUMPRODUCT(ods_project_ids!$N217:$N303, ods_project_ids!W217:W303, --(ods_project_ids!$Y217:$Y303<>"yes")) /SUMPRODUCT(ods_project_ids!$N217:$N303, --(ods_project_ids!$Y217:$Y303<>"yes")) -> 0 | I7: =SUMPRODUCT(ods_project_ids!$N217:$N303, ods_project_ids!X217:X303, --(ods_project_ids!$Y217:$Y303<>"yes")) /SUMPRODUCT(ods_project_ids!$N217:$N303, --(ods_project_ids!$Y217:$Y303<>"yes")) -> 0

Sheet ea_projects
A1: project_id | B1: carb_issuance_id | C1: reporting_period | D1: ratio_CFC-11 | E1: ratio_CFC-12 | F1: ratio_CFC-13 | G1: ratio_CFC-113 | H1: ratio_CFC-114 | I1: ratio_CFC-115 | J1: ratio_HCFC-22 | K1: ratio_HCFC-141b | L1: drop | M1: assumption_tier | N1: document_name | O1: composition_basis | P1: total_weight_lb | Q1: eligible_weight_lb | R1: cfc-11_pct | S1: cfc-12_pct | T1: cfc-13_pct | U1: cfc-113_pct | V1: cfc-114_pct | W1: cfc-115_pct | X1: hcfc-22_pct | Y1: hcfc-141b_pct | Z1: er_tco2e_report | AA1: credits_issued | AB1: er_match | AC1: notes
A2: ACR183 | B2: CAOD0061-A | C2: 1 | E2: 0.9996 | H2: 8e-05 | I2: 0.00032 | M2: A_lab | N2: ACR183 DPC Project #12 Verification Report_Final_revised.pdf | O2: lab_pct | P2: 9300 | Q2: 9093 | S2: 97.47 | V2: 0.01 | W2: 0.09 | Z2: 38517 | AA2: 38517 | AB2: yes | AC2: Lab analysis by National Refrigerants Inc (AHRI-certified): Section 3.1 (total material; eligible material destroyed) '97.47% R-12, 0.01% R-114 and 0.09% R-115'. Section 3.7.2.
A3: ACR184 | B3: CAOD0072-A | C3: 1 | E3: 1 | M3: B_single | N3: VerifReport-EOS-ACR184 RP1_Final_2013-11-05.pdf | O3: purity_gt90 | P3: 30600 | Z3: 126977 | AA3: 126977 | AB3: yes | AC3: 30,600 lb concentrated R-12 (single event, ISO SECU 1220724), destroyed at Clean Harbors El Dorado AR. 'met the 90% purity standard (single species of ODS greater than 90% purity)' — no lab percentages in OVR. AHRI-700-2006 lab, GC/MS. Verifier: NSF-ISR.
A4: ACR184 | B4: CAOD0072-B | C4: 2 | E4: 1 | M4: B_single | N4: VerifReport-EOS-ACR184 P2_2013-11-08.pdf | O4: purity_gt90 | P4: 29540 | Z4: 122048 | AA4: 122048 | AB4: yes | AC4: 29,540 lb concentrated R-12 (single event, ISO SECU 1250502) aggregated at Hudson Technologies from JACO Environmental + 5 suppliers; destroyed at Clean Harbors El Dorado AR. No lab percentages in OVR; material 'met the 90% purity standard (single species of ODS greater than 90% purity)' i.e. R-12 >90%. AHRI-700-2006 lab, GC/MS. ER: 122,048 (baseline 131,994 - project 9,946). Verifier: NSF-ISR.; crediting numbers replicated assuming ~95 percent of material is CFC-12
A5: CAR604 | B5: CAOD0016-C | C5: 1 | E5: 1 | M5: B_single | N5: Project Verification Report -ODS- Project EOS-JA-09-01 2010-04-27.pdf | O5: purity_gt90 | P5: 58730 | Z5: 252970 | AA5: 72960 | AB5: no | AC5: Two destruction events; 58,730 lb of 'mostly refrigerant R-12'. Half-ton cylinders from Jaco Environmental reclaimed by Hudson Technologies (impurities removed), shipped in bulk ISO containers to Clean Harbors El Dorado AR. Lab (AHRI, GC): 'refrigerant in each container was more than 90% CFC-12 by weight.' Report ER 252,970 vs spreadsheet credits 252,960 — 10 tCO2e difference. Verifier: NSF. [Credit issuance 1 of 3 for this RP; RP total 252,960; er_match compares report ER to RP total.]
A6: CAR604 | B6: CAOD0016-C2 | C6: 1 | E6: 1 | M6: B_single | N6: Project Verification Report -ODS- Project EOS-JA-09-01 2010-04-27.pdf | O6: purity_gt90 | P6: 58730 | Z6: 252970 | AA6: 105000 | AB6: no | AC6: Two destruction events; 58,730 lb of 'mostly refrigerant R-12'. Half-ton cylinders from Jaco Environmental reclaimed by Hudson Technologies (impurities removed), shipped in bulk ISO containers to Clean Harbors El Dorado AR. Lab (AHRI, GC): 'refrigerant in each container was more than 90% CFC-12 by weight.' Report ER 252,970 vs spreadsheet credits 252,960 — 10 tCO2e difference. Verifier: NSF. [Credit issuance 2 of 3 for this RP; RP total 252,960; er_match compares report ER to RP total.]
A7: CAR604 | B7: CAOD0016-C3 | C7: 1 | E7: 1 | M7: B_single | N7: Project Verification Report -ODS- Project EOS-JA-09-01 2010-04-27.pdf | O7: purity_gt90 | P7: 58730 | Z7: 252970 | AA7: 75000 | AB7: no | AC7: Two destruction events; 58,730 lb of 'mostly refrigerant R-12'. Half-ton cylinders from Jaco Environmental reclaimed by Hudson Technologies (impurities removed), shipped in bulk ISO containers to Clean Harbors El Dorado AR. Lab (AHRI, GC): 'refrigerant in each container was more than 90% CFC-12 by weight.' Report ER 252,970 vs spreadsheet credits 252,960 — 10 tCO2e difference. Verifier: NSF. [Credit issuance 3 of 3 for this RP; RP total 252,960; er_match compares report ER to RP total.]
A8: CAR604 | B8: CAOD0016-D | C8: 2 | E8: 1 | M8: B_single | N8: Project Verification Report -ODS- Project EOS-JA-09-01 Period 2 07-11-2010 final #2.pdf | O8: purity_gt90 | P8: 62640 | Z8: 250678 | AA8: 192040 | AB8: no | AC8: Two destruction events; 62,640 lb of 'mostly refrigerant R-12'; lab: 'more than 90% CFC-12 by weight' in each container. Same chain as RP1 (Jaco → Hudson → Clean Harbors). MISMATCH: report ER 250,678 vs spreadsheet credits 238,980 (diff 11,698) — possibly partial issuance. Verifier: NSF. [Credit issuance 1 of 4 for this RP; RP total 238,980; er_match compares report ER to RP total.]
A9: CAR604 | B9: CAOD0016-D2 | C9: 2 | E9: 1 | M9: B_single | N9: Project Verification Report -ODS- Project EOS-JA-09-01 Period 2 07-11-2010 final #2.pdf | O9: purity_gt90 | P9: 62640 | Z9: 250678 | AA9: 11940 | AB9: no | AC9: Two destruction events; 62,640 lb of 'mostly refrigerant R-12'; lab: 'more than 90% CFC-12 by weight' in each container. Same chain as RP1 (Jaco → Hudson → Clean Harbors). MISMATCH: report ER 250,678 vs spreadsheet credits 238,980 (diff 11,698) — possibly partial issuance. Verifier: NSF. [Credit issuance 2 of 4 for this RP; RP total 238,980; er_match compares report ER to RP total.]
A10: CAR604 | B10: CAOD0016-D3 | C10: 2 | E10: 1 | M10: B_single | N10: Project Verification Report -ODS- Project EOS-JA-09-01 Period 2 07-11-2010 final #2.pdf | O10: purity_gt90 | P10: 62640 | Z10: 250678 | AA10: 25000 | AB10: no | AC10: Two destruction events; 62,640 lb of 'mostly refrigerant R-12'; lab: 'more than 90% CFC-12 by weight' in each container. Same chain as RP1 (Jaco → Hudson → Clean Harbors). MISMATCH: report ER 250,678 vs spreadsheet credits 238,980 (diff 11,698) — possibly partial issuance. Verifier: NSF. [Credit issuance 3 of 4 for this RP; RP total 238,980; er_match compares report ER to RP total.]
A11: CAR604 | B11: CAOD0016-D4 | C11: 2 | E11: 1 | M11: B_single | N11: Project Verification Report -ODS- Project EOS-JA-09-01 Period 2 07-11-2010 final #2.pdf | O11: purity_gt90 | P11: 62640 | Z11: 250678 | AA11: 10000 | AB11: no | AC11: Two destruction events; 62,640 lb of 'mostly refrigerant R-12'; lab: 'more than 90% CFC-12 by weight' in each container. Same chain as RP1 (Jaco → Hudson → Clean Harbors). MISMATCH: report ER 250,678 vs spreadsheet credits 238,980 (diff 11,698) — possibly partial issuance. Verifier: NSF. [Credit issuance 4 of 4 for this RP; RP total 238,980; er_match compares report ER to RP total.]
A12: CAR604 | B12: CAOD0016-A | C12: 3 | E12: 1 | M12: B_single | N12: Project Verification Report -ODS- Project EOS-JA-09-01 3rd Period 2010-08-06.pdf | O12: purity_gt90 | P12: 25800 | Z12: 105730 | AA12: 49000 | AB12: no | AC12: One destruction event; 25,800 lb 'mostly refrigerant R-12'; lab: 'more than 90% CFC-12 by weight'. MISMATCH: report ER 105,730 vs spreadsheet RP3 credits 49,000 — spreadsheet RP numbering may not align with CAR registry report numbering. Verifier: NSF.
A13: CAR604 | C13: 4 (not in issuance table) | L13: yes | M13: C_mixed_fill1 | N13: Project Verification Report-ODS-Project EOS-JA-09-01 4th Rpt Period 2010-09-28.pdf | O13: mixed_unspecified | P13: 23800 | Z13: 61775 | AA13: 0 | AB13: n/a | AC13: One destruction event; 23,800 lb 'comprised mostly of R-114 and R-11'; lab: 'a mixture of R-114 and R-11, with small amounts of R-12 and R-115' — no percentages. Spreadsheet has no RP4 row for CAR604; included for completeness. Verifier: NSF.
A14: CAR604 | B14: CAOD0016-E | C14: 5 | E14: 1 | M14: A_lab | N14: Verification Report-ODS-EOS-JA-09-01 5th Per 2010-11-16 signed.pdf | O14: lab_pct | P14: 33200 | S14: 95.94 | Z14: 138575 | AA14: 138575 | AB14: yes | AC14: One destruction event; 33,200 lb of R-12 in one bulk ISO container (Hudson Technologies → Clean Harbors El Dorado AR). Lab (AHRI-700-2006, GC): 'the refrigerant was R-12 at a purity level of 95.94%'. Verifier: NSF-ISR.
A15: CAR604 | B15: CAOD0016-F | C15: 6 | E15: 1 | M15: A_lab | N15: Verification Report-ODS-EOS-JA-09-01 6th Per 2010-12-11.pdf | O15: lab_pct | P15: 26120 | S15: 91.19 | Z15: 103494 | AA15: 103494 | AB15: yes | AC15: One destruction event; 26,120 lb of R-12 (Hudson Technologies → Clean Harbors El Dorado AR). Lab (AHRI-700-2006, GC): 'the refrigerant was R-12 at a purity level of 91.19%'. Verifier: NSF-ISR.
A16: CAR604 | B16: CAOD0016-B | C16: 7 | L16: yes | M16: C_mixed_fill1 | N16: Verification Report-ODS-EOS-JA-09-01 7th Per 2011-02-23 rev 1.pdf | O16: mixed_unspecified | P16: 56400 | Z16: 176882 | AA16: 150000 | AB16: yes | AC16: Two destruction events; 56,400 lb of 'R-12 mixed refrigerant'. MIXED — 'did not meet the 90% purity standard'; no species breakdown. Two ISO tanks aggregated/sampled at Hudson Technologies; AHRI lab, GC. Verifier: NSF-ISR. [Credit issuance 1 of 2 for this RP; RP total 176,882; er_match compares report ER to RP total.]; using average fill values overcredits by 20% indicating too much cfc-12 by
A17: CAR604 | B17: CAOD0016-B2 | C17: 7 | L17: yes | M17: C_mixed_fill1 | N17: Verification Report-ODS-EOS-JA-09-01 7th Per 2011-02-23 rev 1.pdf | O17: mixed_unspecified | P17: 56400 | Z17: 176882 | AA17: 26882 | AB17: yes | AC17: Two destruction events; 56,400 lb of 'R-12 mixed refrigerant'. MIXED — 'did not meet the 90% purity standard'; no species breakdown. Two ISO tanks aggregated/sampled at Hudson Technologies; AHRI lab, GC. Verifier: NSF-ISR. [Credit issuance 2 of 2 for this RP; RP total 176,882; er_match compares report ER to RP total.]
A18: CAR604 | B18: CAOD0016-G | C18: 8 | L18: yes | M18: C_mixed_fill1 | N18: Verification_Report_RptPer8_2011-02-25.pdf | O18: mixed_unspecified | P18: 26360 | Z18: 57125 | AA18: 23118 | AB18: yes | AC18: MIXED ODS (<90% purity): 'one container of mixed ODS, i.e. R-12, R-11, R-114, R-115 refrigerant', aggregated at Hudson Technologies (Champaign IL), destroyed at Clean Harbors El Dorado AR. No species percentage breakdown in report; AHRI-700-2006 lab via GC. Verifier: NSF-ISR. [Credit issuance 1 of 2 for this RP; RP total 57,125; er_match compares report ER to RP total.]
A19: CAR604 | B19: CAOD0016-G2 | C19: 8 | L19: yes | M19: C_mixed_fill1 | N19: Verification_Report_RptPer8_2011-02-25.pdf | O19: mixed_unspecified | P19: 26360 | Z19: 57125 | AA19: 34007 | AB19: yes | AC19: MIXED ODS (<90% purity): 'one container of mixed ODS, i.e. R-12, R-11, R-114, R-115 refrigerant', aggregated at Hudson Technologies (Champaign IL), destroyed at Clean Harbors El Dorado AR. No species percentage breakdown in report; AHRI-700-2006 lab via GC. Verifier: NSF-ISR. [Credit issuance 2 of 2 for this RP; RP total 57,125; er_match compares report ER to RP total.]
A20: CAR628 | B20: CAOD0092-A | C20: 2 | L20: yes | M20: C_mixed_fill1 | N20: GHG_Project_Verification_Report_RefEx_10_13_12 rev w corrections.pdf | O20: mixed_unspecified | Q20: 6459 | Z20: 12510 | AA20: 12510 | AB20: yes | AC20: MIXED ODS (<90% purity): 'mixed ODS (i.e. R-11, R-12, R-114, R-115 <90% purity) refrigerant obtained from sources in the United States, primarily California' (10 half-ton containers). Destroyed at RemTec International (argon arc plasma), Bowling Green OH. No species breakdown. Verifier: NSF-ISR.
A21: CAR781 | B21: CAOD0076-A | C21: 1 | D21: 1 | M21: A_lab | N21: Pure Chem ODS Verification Report Version-Final.pdf | O21: lab_pct | P21: 21480 | R21: 91.5 | Z21: 35437 | AA21: 27437 | AB21: no | AC21: CFC-11 destruction: lab analysis (National Refrigerants Inc, AHRI-certified) 'purity of R-11 (CFC-11) which was 91.50%'. 21,480 lb on COD (ISO tank 60692), destroyed at Clean Harbors El Dorado AR. Material was residue from pharmaceutical-grade purification for a manufacturer. MISMATCH: report ER 35,437 tCO2e vs spreadsheet credits 27,437 (diff exactly 8,000 — possible buffer/other issuance). Verifier: Ruby Canyon Engineering.
A22: CAR784 | B22: CAOD0005-A | C22: 1 | E22: 1 | M22: B_single | N22: Final_ECC-ODS_PA_001VerificationReport.pdf | O22: purity_gt90 | P22: 24895 | Z22: 106398 | AA22: 100000 | AB22: yes | AC22: Two destruction events at Clean Harbors El Dorado AR (COD ZIPU-6401635: 21,360 lb; COD SA4346: 3,535 lb). Lab (National Refrigerants, GC): both non-mixed ODS with 'R12 composition of greater than 90% by weight'; R11/R114/R115 + contaminants <10%. Developer: Environmental Credit Corp. Verifier: TÜV SÜD. [Credit issuance 1 of 2 for this RP; RP total 106,398; er_match compares report ER to RP total.]
A23: CAR784 | B23: CAOD0005-A2 | C23: 1 | E23: 1 | M23: B_single | N23: Final_ECC-ODS_PA_001VerificationReport.pdf | O23: purity_gt90 | P23: 24895 | Z23: 106398 | AA23: 6398 | AB23: yes | AC23: Two destruction events at Clean Harbors El Dorado AR (COD ZIPU-6401635: 21,360 lb; COD SA4346: 3,535 lb). Lab (National Refrigerants, GC): both non-mixed ODS with 'R12 composition of greater than 90% by weight'; R11/R114/R115 + contaminants <10%. Developer: Environmental Credit Corp. Verifier: TÜV SÜD. [Credit issuance 2 of 2 for this RP; RP total 106,398; er_match compares report ER to RP total.]
A24: CAR784 | B24: CAOD0005-C | C24: 2 | L24: yes | M24: C_mixed_fill1 | N24: ECC-ODS-PA-001 2nd VerificationReport_revised.pdf | O24: mixed_unspecified | P24: 33360 | Z24: 109653 | AA24: 109653 | AB24: yes | AC24: One destruction event at Clean Harbors El Dorado AR (COD ZIPU-6401912). Lab (GC): 'mixed ODS with R12 composition of less than 90% by weight'; R11/R114/R115 + contaminants <10%; no exact percentages. Mixed-ODS circulation/sampling at Safe Disposal Systems (EPA Certified Reclaimer). Developer: ECC. Verifier: TÜV SÜD.
A25: CAR784 | B25: CAOD0005-B | C25: 3 | L25: yes | M25: C_mixed_fill1 | N25: ECC-ODS-PA-001 3rd VerificationReport.pdf | O25: mixed_unspecified | P25: 30600 | Z25: 94621 | AA25: 94621 | AB25: yes | AC25: One destruction event at Clean Harbors El Dorado AR (COD ZIPU-6401635-08-09-11). Lab (GC): 'mixed ODS with R11 and R12 compositions of less than 90% by weight'; R114/R115 + contaminants also present; no exact percentages. Developer: ECC. Verifier: TÜV SÜD.
A26: CAR786 | B26: CAOD0069-A | C26: 2 | E26: 1 | M26: B_single | N26: ECC-ODS-CA-002 Ver#2_VerificationReport_Revised.pdf | O26: purity_gt90 | P26: 11032 | Z26: 47593 | AA26: 27951 | AB26: no | AC26: One destruction event at Clean Harbors El Dorado AR (COD BOL6724653); 11,032 lb R-12 sourced from ARCA appliance recoveries (Compton CA). Lab (GC): 'non-mixed ODS with R12 composition of greater than 90% by weight'; R11/R114 + contaminants <10%. MISMATCH: report ER 47,593 vs spreadsheet credits 27,951 (diff 19,642). Developer: ECC. Verifier: TÜV SÜD.
A27: CAR795 | B27: CAOD0065-A | C27: 1 | E27: 1 | M27: A_lab_multi | N27: WSO 2011-1 V1.2.pdf | O27: lab_pct_per_container | P27: 7799 | Z27: 33097 | AA27: 33097 | AB27: yes | AC27: 9 half-ton cylinders of CFC-12 destroyed at Clean Harbors El Dorado AR (2 CODs); 7,799 lb total. Per-cylinder lab purity (National Refrigerants Inc), '% by weight of CFC-12': range 95.42%–99.66% across cylinders (Table 3). Verifier: Ruby Canyon Engineering.
A28: CAR795 | B28: CAOD0065-B | C28: 2 | E28: 1 | M28: A_lab_multi | N28: WSO 2011 1 RP2 Verification Report Final.pdf | O28: lab_pct_per_container | P28: 15269 | Z28: 54406 | AA28: 54406 | AB28: yes | AC28: CFC-12 destruction at Clean Harbors El Dorado AR; 15,269 lb total across multiple CODs. Lab (National Refrigerants Inc): mixed material 'ranged from 73.53% to 75.58% R-12' and pure material 'ranged from 91.86% to 93.19% R-12'. Verifier: Ruby Canyon Engineering.
A29: CAR804 | B29: CAOD0017-G | C29: 1 | L29: yes | M29: C_mixed_fill1 | N29: VerifReport-EOS-CAR2011DomesticP2R12011-05-18[1]final.pdf | O29: mixed_and_pure_unspecified | P29: 50220 | Z29: 113474 | AA29: 63474 | AB29: yes | AC29: Two destruction events at Clean Harbors El Dorado AR: 28,360 lb 'R-12 mixed refrigerant' (<90% purity) + 21,860 lb 'pure R-12' (>90% purity); aggregated at Hudson Technologies. No exact percentages. Verifier: NSF-ISR. [Credit issuance 1 of 2 for this RP; RP total 113,474; er_match compares report ER to RP total.]
A30: CAR804 | B30: CAOD0017-G2 | C30: 1 | L30: yes | M30: C_mixed_fill1 | N30: VerifReport-EOS-CAR2011DomesticP2R12011-05-18[1]final.pdf | O30: mixed_and_pure_unspecified | P30: 50220 | Z30: 113474 | AA30: 50000 | AB30: yes | AC30: Two destruction events at Clean Harbors El Dorado AR: 28,360 lb 'R-12 mixed refrigerant' (<90% purity) + 21,860 lb 'pure R-12' (>90% purity); aggregated at Hudson Technologies. No exact percentages. Verifier: NSF-ISR. [Credit issuance 2 of 2 for this RP; RP total 113,474; er_match compares report ER to RP total.]
A31: CAR804 | B31: CAOD0017-B | C31: 2 | L31: yes | M31: C_mixed_fill1 | N31: VerificationReport-EOS-CAR2011DomesticP2R2_05-30-2011.pdf | O31: mixed_unspecified | P31: 24960 | Z31: 87641 | AA31: 87641 | AB31: yes | AC31: "In this reporting period EOS Climate acquired 14,352 lbs. pounds of mixed ODS (R-12, R-11, R-114, R-115) from Hudson Technologies and 10,768 lbs. pounds of pure R-12 (ranging from 95.2-99.99%)"; Verifier: NSF-ISR.
A32: CAR804 | B32: CAOD0017-A | C32: 3 | D32: 0.2376 | E32: 0.7624 | F32: 0 | G32: 0 | H32: 0 | I32: 0 | J32: 0 | K32: 0 | M32: A_lab_mixed | N32: VerifReport-EOS-CAR2011DomesticP2R3_07-22-2011.pdf | O32: purity_gt90 | P32: 15220 | Z32: 47339 | AA32: 37359 | AB32: yes | AC32: Two destruction events at Clean Harbors El Dorado AR; 15,220 lb: 'two ISO containers of pure ODS (i.e. >90% R-12 or R-11)' from a reclaimer in Nashville TN. Verifier: NSF-ISR. [Credit issuance 1 of 2 for this RP; RP total 47,339; er_match compares report ER to RP total.]
A33: CAR804 | B33: CAOD0017-A2 | C33: 3 | D33: 0.2376 | E33: 0.7624 | F33: 0 | G33: 0 | H33: 0 | I33: 0 | J33: 0 | K33: 0 | M33: A_lab_mixed | N33: VerifReport-EOS-CAR2011DomesticP2R3_07-22-2011.pdf | O33: purity_gt90 | P33: 15220 | Z33: 47339 | AA33: 9980 | AB33: yes | AC33: Two destruction events at Clean Harbors El Dorado AR; 15,220 lb: 'two ISO containers of pure ODS (i.e. >90% R-12 or R-11)' from a reclaimer in Nashville TN. Verifier: NSF-ISR. [Credit issuance 2 of 2 for this RP; RP total 47,339; er_match compares report ER to RP total.]
A34: CAR804 | B34: CAOD0017-D | C34: 4 | L34: yes | M34: C_mixed_fill1 | N34: VerifReport-EOS-CAR2011DomesticP2R4_08-08-2011_Final rev.1.pdf | O34: mixed_unspecified | P34: 51080 | Z34: 145023 | AA34: 127688 | AB34: no | AC34: Two destruction events at Clean Harbors El Dorado AR; 51,080 lb mixed ODS refrigerant (<90% purity) from Hudson Technologies (Champaign IL); species not listed; no breakdown. MISMATCH: report ER 145,023 vs spreadsheet credits 127,688 (diff 17,335). Verifier: NSF-ISR.
A35: CAR804 | B35: CAOD0017-E | C35: 5 | L35: yes | M35: C_mixed_fill1 | N35: VerifReport-EOS-CAR2011DomesticP2R5_10-12-2011 Rev 3.pdf | O35: mixed_unspecified | P35: 39080 | Z35: 118092 | AA35: 117427 | AB35: no | AC35: Two destruction events at Clean Harbors El Dorado AR; 39,080 lb ODS refrigerant; at least one container mixed (<90% purity) from Polar Technology facility; species not listed. SLIGHT MISMATCH: report ER 118,092 vs spreadsheet credits 117,427 (diff 665). Verifier: NSF-ISR.
A36: CAR804 | B36: CAOD0017-F | C36: 6 | E36: 1 | M36: A_lab | N36: VerifReport-EOS-CAR2011DomesticP2R6_11-09-2011 rev.2.pdf | O36: lab_pct | P36: 15480 | S36: 99.16 | Z36: 67022 | AA36: 67022 | AB36: yes | AC36: One destruction event at Clean Harbors El Dorado AR; 15,480 lb 'pure R-12 (approximately 99.16%)' from JACO Environmental facilities (ISO container #1221572). Verifier: NSF-ISR.
A37: CAR804 | B37: CAOD0017-C | C37: 7 | L37: yes | M37: C_mixed_fill1 | N37: VerifReport-EOS-CAR2011DomesticP2R7_2011-12-12.pdf | O37: mixed_and_pure_unspecified | P37: 26740 | Z37: 87863 | AA37: 87863 | AB37: yes | AC37: Two destruction events at Clean Harbors El Dorado AR; 26,740 lb total: 16,320 lb concentrated R-12 (>90%, ISO #1220724, JACO + Hudson) + 10,420 lb mixed R-12 (<90%, ISO #1221588, Polar Technology). No exact percentages. Verifier: NSF-ISR.
A38: CAR805 | B38: CAOD0077-A | C38: 1 | E38: 0.69139 | H38: 0.30456 | I38: 0.00405 | M38: A_lab | N38: Pure Chem ODS Destruction Project #3_Verification Report_Final.pdf | O38: lab_pct | P38: 32560 | S38: 34.88 | V38: 20.81 | W38: 0.59 | Z38: 55730 | AA38: 55730 | AB38: yes | AC38: "All parameters of the analysis exceeded the requirements of the protocol including the purity of R‐12 which was 34.88%, R‐114 which was 20.81%, and R‐115 which was 0.59%."
A39: CAR818 | B39: CAOD0053-B | C39: 1 | L39: yes | M39: C_mixed_fill1 | N39: VerifReport-RemTec-CAR2011DomesticP1R1_08-28-2011.pdf | O39: mixed_unspecified | P39: 31512 | Z39: 95487 | AA39: 95487 | AB39: yes | AC39: One destruction event at RemTec, Bowling Green OH; 31,512 lb 'mixed ODS (i.e. R-12, R-11, R-114, R-115)' (<90% purity); 28 containers aggregated into one 5,500-gal tank; no species breakdown. Verifier: NSF-ISR.
A40: CAR818 | B40: CAOD0053-C | C40: 2 | L40: yes | M40: C_mixed_fill1 | N40: VerifReport-RemTec-CAR2011DomesticP1R2_11-15-2011.pdf | O40: mixed_unspecified | P40: 17120 | Z40: 24912 | AA40: 24912 | AB40: yes | AC40: One destruction event at RemTec, Bowling Green OH; 17,120 lb mixed ODS refrigerant (<90% purity); 19 containers aggregated into one 5,500-gal tank; no species breakdown. Verifier: NSF-ISR.
...

Sheet template_2014_foam
C1: Mass ODS (lb) | D1: CFC-11 (mass%) | E1: CFC-12 (mass%) | F1: CFC-13 (mass%) | G1: CFC-113 (mass%) | H1: CFC-114 (mass%) | I1: CFC-115 (mass%) | J1: HCFC-22 (mass%) | K1: HCFC-141b (mass%)
B2: 1 | C2: 13221 | D2: 16.25 | E2: 66.57 | F2: 0 | G2: 0 | H2: 3.52 | I2: 1.22 | J2: 0 | K2: 0
B3: 2 | C3: 9904 | D3: 0.02 | E3: 97.01 | F3: 0 | G3: 0 | H3: 0 | I3: 0.01 | J3: 0 | K3: 0
B4: 3 | C4: 12162 | D4: 0.05 | E4: 98.86 | F4: 0 | G4: 0.01 | H4: 0 | I4: 0.01 | J4: 0 | K4: 0
B5: 4
B6: 5
B8: mass eligible ods sent for destruction (lbsODS) | C8: =sum(D8:K8) -> 33219.016 | D8: =(D5/100)*$C5 + (D4/100)*$C4 + (D3/100)*$C3+ (D2/100)*$C2 + (D6/100)*$C6 -> 2156.4743 | E8: =(E5/100)*$C5 + (E4/100)*$C4 + (E3/100)*$C3+ (E2/100)*$C2 + (E6/100)*$C6 -> 30432.443 | F8: =(F5/100)*$C5 + (F4/100)*$C4 + (F3/100)*$C3+ (F2/100)*$C2 + (F6/100)*$C6 -> 0 | G8: =(G5/100)*$C5 + (G4/100)*$C4 + (G3/100)*$C3+ (G2/100)*$C2 + (G6/100)*$C6 -> 1.2162 | H8: =(H5/100)*$C5 + (H4/100)*$C4 + (H3/100)*$C3+ (H2/100)*$C2 + (H6/100)*$C6 -> 465.3792 | I8: =(I5/100)*$C5 + (I4/100)*$C4 + (I3/100)*$C3+ (I2/100)*$C2 + (I6/100)*$C6 -> 163.5028 | J8: =(J5/100)*$C5 + (J4/100)*$C4 + (J3/100)*$C3+ (J2/100)*$C2 + (J6/100)*$C6 -> 0 | K8: =(K5/100)*$C5 + (K4/100)*$C4 + (K3/100)*$C3+ (K2/100)*$C2 + (K6/100)*$C6 -> 0
A9: Q_refr,i | B9: mass eligible ods sent for destruction (mtODS) | C9: =sum(D9:K9) -> 15.067813 | D9: =D8*0.00045359 -> 0.97815518 | E9: =E8*0.00045359 -> 13.803852 | F9: =F8*0.00045359 -> 0 | G9: =G8*0.00045359 -> 0.00055165616 | H9: =H8*0.00045359 -> 0.21109135 | I9: =I8*0.00045359 -> 0.074163235 | J9: =J8*0.00045359 -> 0 | K9: =K8*0.00045359 -> 0
B11: project baseline emissions (mtco2e) | C11: 328617
A12: BE (Eq 5.2) | B12: project baseline emissions (mtCO2e) | C12: =sum(C14) -> 149056.98
A14: BE_refr (Eq 5.3) | B14: mass baseline emissions from regrigerant ODS (mtCO2e) | C14: =sum(D14:K14) -> 149056.98 | D14: =D9*D15*D16 -> 4135.151 | E14: =E9*E15*E16 -> 142938.89 | F14: =F9*F15*F16 -> 0 | G14: =G9*G15*G16 -> 3.0096705 | H14: =H9*H15*H16 -> 1646.5125 | I14: =I9*I15*I16 -> 333.41566 | J14: =J9*J15*J16 -> 0 | K14: =K9*K15*K16 -> 0
A15: ER_refr,i (Table B.1) | B15: 10-year cumulative emission rate for refrigerant ODS (..) | D15: 0.89 | E15: 0.95 | F15: 0.61 | G15: 0.89 | H15: 0.78 | I15: 0.61
A16: GWP_i (Table B.1) | B16: GWP ODS (mtCO2e / mtODS) | D16: 4750 | E16: 10900 | F16: 14400 | G16: 6130 | H16: 10000 | I16: 7370 | J16: 1810 | K16: 725
A18: BE_foam (Eq 5.4) | B18: mass baseline emissions from ODS blowing agent (mtCO2e) | C18: 0
A19: GWP_i (Table B.2) | B19: GWP ODS (mtCO2e / mtODS) | D19: 4750 | E19: 10900 | J19: 1810 | K19: 725
A20: ER_i,app (Table B.2) | B20: appliance ODS blowing agent 10-year ER | D20: 0.44 | E20: 0.55 | J20: 0.75 | K20: 0.5
A21: ER_i,build (Table B.2) | B21: building ODS blowing agent 10-year ER | D21: 0.2 | E21: 0.36 | J21: 0.65 | K21: 0.29
